Workbook

Sheet Sheet1
A1: Emp_ID | B1: First_Name | C1: Last_Name | D1: Gender | E1: Department | F1: Salary | G1: Salary_Bucket | H1: Start_Date | I1: FTE | J1: Employee type | K1: Work_location | L1: Tenure | M1: Work_Type
A2: PR73015 | B2: Minerva | C2: Nelson | D2: Female | E2: Engineering | F2: 76 | G2: 309 | H2: 50k to 100k | I2: 46319 | J2: 0.8 | K2: Permanent | L2: Sydney | M2: Australia | N2: 9.35 | O2: Contract
A3: PR11892 | B3: Ingrid | C3: Brown | D3: Male | E3: Product Management | F3: 74 | G3: 108 | H3: 50k to 100k | I3: 46228 | J3: 0.4 | K3: Permanent | L3: Sydney | M3: Australia | N3: 1.54 | O3: Part time
A4: PR73751 | B4: Manfred | C4: {=_xlfn._xlws.FILTER(Sheet1!A2:O201,Sheet1!B2:B201)} -> #VALUE! | D4: Female | E4: Customer Service | F4: 83 | G4: 238 | H4: 50k to 100k | I4: 46161 | J4: 0.4 | K4: Temporary | L4: Remote | M4: 3.85 | N4: Full time
A5: PR96753 | B5: Anna | C5: Scott | D5: Male | E5: Product Management | F5: 34 | G5: 792 | H5: Under 50k | I5: 46250 | J5: 0.7 | K5: Contract | L5: Chicago | M5: USA | N5: 2.15 | O5: Full time
A6: PR91404 | B6: Michael | C6: Mitchell | D6: Male | E6: Finance | F6: 156 | G6: 732 | H6: Above 100k | I6: 46126 | J6: 0.6 | K6: Permanent | L6: New York | M6: USA | N6: 8.19 | O6: Freelance
A7: PR26442 | B7: Andreas | C7: Smith | D7: Male | E7: IT | F7: 143 | G7: 894 | H7: Above 100k | I7: 46094 | J7: 0.4 | K7: Permanent | L7: Sydney | M7: Australia | N7: 1.11 | O7: Contract
A8: PR42680 | B8: Jill | C8: Adams | D8: Male | E8: Business Development | F8: 54 | G8: 501 | H8: 50k to 100k | I8: 46075 | J8: 0.9 | K8: Contract | L8: Toronto | M8: Canada | N8: 4.46 | O8: Part time
A9: PR37088 | B9: Günter | C9: =VLOOKUP(C6,Sheet1!A2:O201,Sheet1!B2) -> #N/A | D9: Female | E9: Operations | F9: 64 | G9: 899 | H9: 50k to 100k | I9: 46053 | J9: 0.4 | K9: Permanent | L9: Tokyo | M9: Japan | N9: 1.43 | O9: Contract
A10: PR44252 | B10: Robert | C10: King | D10: Female | E10: Finance | F10: 70 | G10: 476 | H10: 50k to 100k | I10: 46383 | J10: 0.6 | K10: Contract | L10: New York | M10: USA | N10: 7.67 | O10: Freelance
A11: PR43906 | B11: Horst | C11: Perez | D11: Female | E11: Marketing | F11: 107 | G11: 996 | H11: Above 100k | I11: 46055 | J11: 0.8 | K11: Contract | L11: Hyderabad | M11: India | N11: 6.43 | O11: Part time
A12: PR40245 | B12: Ursula | C12: Hill | D12: Male | E12: Data Analytics | F12: 136 | G12: 213 | H12: Above 100k | I12: 46332 | J12: 0.7 | K12: Permanent | L12: London | M12: UK | N12: 7.74 | O12: Part time
A13: PR47648 | B13: Brigitte | C13: Turner | D13: Female | E13: Data Analytics | F13: 164 | G13: 32 | H13: Above 100k | I13: 46366 | J13: 0.4 | K13: Temporary | L13: Remote | M13: 5.6 | N13: Part time
A14: PR19000 | B14: Ingrid | C14: Davis | D14: Male | E14: Accounting | F14: 64 | G14: 987 | H14: 50k to 100k | I14: 46070 | J14: 0.4 | K14: Temporary | L14: Singapore | M14: 9.29 | N14: Full time
A15: PR66843 | B15: David | C15: Torres | D15: Female | E15: IT | F15: 73 | G15: 276 | H15: 50k to 100k | I15: 46264 | J15: 0.6 | K15: Contract | L15: Paris | M15: France | N15: 7.77 | O15: Part time
A16: PR71131 | B16: Manfred | C16: Phillips | D16: Female | E16: Sales | F16: 128 | G16: 485 | H16: Above 100k | I16: 46030 | J16: 0.9 | K16: Permanent | L16: London | M16: UK | N16: 0.64 | O16: Freelance
A17: PR16247 | B17: Peter | C17: Burnsyde | D17: Female | E17: Accounting | F17: 64 | G17: 772 | H17: 50k to 100k | I17: 46151 | J17: 0.9 | K17: Contract | L17: Paris | M17: France | N17: 5.26 | O17: Freelance
A18: PR55662 | B18: Dieter | C18: Young | D18: Female | E18: Operations | F18: 119 | G18: 389 | H18: Above 100k | I18: 46108 | J18: 0.6 | K18: Permanent | L18: Remote | M18: 1.32 | N18: Full time
A19: PR25096 | B19: Beryl | C19: Davis | D19: Male | E19: Human Resources | F19: 105 | G19: 544 | H19: Above 100k | I19: 46371 | J19: 0.9 | K19: Permanent | L19: Hyderabad | M19: India | N19: 7.01 | O19: Full time
A20: PR18560 | B20: Petra | C20: Anderson | D20: Female | E20: Legal | F20: 50 | G20: 675 | H20: 50k to 100k | I20: 46141 | J20: 0.9 | K20: Contract | L20: Mumbai | M20: India | N20: 3.38 | O20: Contract
A21: PR56147 | B21: Julia | C21: Fellgate | D21: Male | E21: Training | F21: 179 | G21: 673 | H21: Above 100k | I21: 46054 | J21: 0.4 | K21: Temporary | L21: London | M21: UK | N21: 9.86 | O21: Freelance
A22: PR70854 | B22: Helmut | C22: Garcia | D22: Female | E22: Accounting | F22: 99 | G22: 185 | H22: 50k to 100k | I22: 46061 | J22: 0.3 | K22: Permanent | L22: Remote | M22: 3.26 | N22: Full time
A23: PR14120 | B23: Van | C23: Augar | D23: Male | E23: Engineering | F23: 69 | G23: 361 | H23: 50k to 100k | I23: 46076 | J23: 0.6 | K23: Temporary | L23: Dubai | M23: UAE | N23: 6.48 | O23: Part time
A24: PR32576 | B24: Emma | C24: Moore | D24: Female | E24: Product Management | F24: 118 | G24: 728 | H24: Above 100k | I24: 46049 | J24: 0.6 | K24: Contract | L24: Dubai | M24: UAE | N24: 5.71 | O24: Part time
A25: PR95083 | B25: Monika | C25: Harris | D25: Female | E25: Accounting | F25: 35 | G25: 358 | H25: Under 50k | I25: 46101 | J25: 0.4 | K25: Temporary | L25: New York | M25: USA | N25: 6.37 | O25: Freelance
A26: PR34510 | B26: Sarah | C26: Clark | D26: Male | E26: Product Management | F26: 148 | G26: 806 | H26: Above 100k | I26: 46091 | J26: 0.4 | K26: Contract | L26: Columbus | M26: USA | N26: 2.05 | O26: Full time
A27: PR23233 | B27: Klaus | C27: Burnsyde | D27: Male | E27: Customer Service | F27: 170 | G27: 775 | H27: Above 100k | I27: 46167 | J27: 0.4 | K27: Permanent | L27: Berlin | M27: Germany | N27: 2.97 | O27: Part time
A28: PR63739 | B28: Elfriede | C28: Green | D28: Male | E28: Data Analytics | F28: 104 | G28: 718 | H28: Above 100k | I28: 46108 | J28: 0.4 | K28: Temporary | L28: Toronto | M28: Canada | N28: 8.49 | O28: Part time
A29: PR34176 | B29: Lalitchandra | C29: Lewis | D29: Male | E29: Customer Service | F29: 29 | G29: 517 | H29: Under 50k | I29: 46181 | J29: 0.6 | K29: Permanent | L29: Berlin | M29: Germany | N29: 8.77 | O29: Freelance
A30: PR74817 | B30: Lalitchandra | C30: Davis | D30: Male | E30: Data Analytics | F30: 46 | G30: 64 | H30: Under 50k | I30: 46200 | J30: 0.3 | K30: Permanent | L30: Dubai | M30: UAE | N30: 6.71 | O30: Contract
A31: PR78417 | B31: Erich | C31: Lewis | D31: Female | E31: Research and Development | F31: 155 | G31: 265 | H31: Above 100k | I31: 46090 | J31: 0.6 | K31: Contract | L31: Toronto | M31: Canada | N31: 6.13 | O31: Contract
A32: PR42580 | B32: Dieter | C32: Jones | D32: Female | E32: Product Management | F32: 112 | G32: 393 | H32: Above 100k | I32: 46266 | J32: 0.9 | K32: Contract | L32: Chicago | M32: USA | N32: 2.59 | O32: Full time
A33: PR81010 | B33: Van | C33: Wright | D33: Female | E33: Training | F33: 36 | G33: 809 | H33: Under 50k | I33: 46103 | J33: 0.4 | K33: Permanent | L33: Wellington | M33: New Zealand | N33: 0.87 | O33: Part time
A34: PR61931 | B34: Lothar | C34: Anderson | D34: Male | E34: Marketing | F34: 94 | G34: 379 | H34: 50k to 100k | I34: 46023 | J34: 0.6 | K34: Contract | L34: Sydney | M34: Australia | N34: 4.12 | O34: Contract
... A38: PR48030 | B38: Brigitte | C38: Walker | D38: Male | E38: Research and Development | F38: 35 | G38: 442 | H38: Under 50k | I38: 46223 | J38: 1 | K38: Contract | L38: Dubai | M38: UAE | N38: 9.13 | O38: Contract
A39: PR72197 | B39: Maria | C39: Flores | D39: Male | E39: Human Resources | F39: 130 | G39: 11 | H39: Above 100k | I39: 46355 | J39: 0.4 | K39: Temporary | L39: Remote | M39: 3.8 | N39: Contract
A40: PR47581 | B40: Brigitte | C40: Hall | D40: Male | E40: Engineering | F40: 135 | G40: 959 | H40: Above 100k | I40: 46172 | J40: 0.9 | K40: Permanent | L40: Remote | M40: 5.46 | N40: Part time
A41: PR89785 | B41: Maria | C41: Veeravasarapu | D41: Male | E41: Training | F41: 169 | G41: 133 | H41: Above 100k | I41: 46352 | J41: 0.5 | K41: Permanent | L41: Remote | M41: 6.71 | N41: Contract
A42: PR18247 | B42: James | C42: Ricardot | D42: Female | E42: Data Analytics | F42: 99 | G42: 278 | H42: 50k to 100k | I42: 46126 | J42: 0.7 | K42: Contract | L42: Remote | M42: 7.36 | N42: Full time
A43: PR33378 | B43: Erich | C43: Harris | D43: Female | E43: Legal | F43: 127 | G43: 989 | H43: Above 100k | I43: 46364 | J43: 0.8 | K43: Contract | L43: Toronto | M43: Canada | N43: 3.6 | O43: Freelance
...

Sheet Average
D3: Department | E3: Head Count | F3: Total Salary | G3: Avg. Salary | H3: 10% Increase
D4: Engineering | E4: =COUNTIFS(Sheet1!E2:E201,Average!D4) -> 15 | F4: =SUMIFS(Sheet1!F2:F201,Sheet1!E2:E201,Average!D4) -> 1490 | G4: =AVERAGEIFS(Sheet1!F2:F201,Sheet1!E2:E201,Average!D4) -> 99.333333 | H4: =F4*1.1 -> 1639
D5: Product Management | E5: =COUNTIFS(Sheet1!E3:E202,Average!D5) -> 11 | F5: =SUMIFS(Sheet1!F3:F202,Sheet1!E3:E202,Average!D5) -> 1206 | G5: =AVERAGEIFS(Sheet1!F3:F202,Sheet1!E3:E202,Average!D5) -> 109.63636 | H5: =F5*110/100 -> 1326.6
D6: Customer Service | E6: =COUNTIFS(Sheet1!E4:E203,Average!D6) -> 15 | F6: =SUMIFS(Sheet1!F4:F203,Sheet1!E4:E203,Average!D6) -> 1609 | G6: =AVERAGEIFS(Sheet1!F4:F203,Sheet1!E4:E203,Average!D6) -> 107.26667 | H6: =F6*110/100 -> 1769.9
D7: Finance | E7: =COUNTIFS(Sheet1!E5:E204,Average!D7) -> 13 | F7: =SUMIFS(Sheet1!F5:F204,Sheet1!E5:E204,Average!D7) -> 1166 | G7: =AVERAGEIFS(Sheet1!F5:F204,Sheet1!E5:E204,Average!D7) -> 89.692308 | H7: =F7*110/100 -> 1282.6
D8: IT | E8: =COUNTIFS(Sheet1!E6:E205,Average!D8) -> 11 | F8: =SUMIFS(Sheet1!F6:F205,Sheet1!E6:E205,Average!D8) -> 1223 | G8: =AVERAGEIFS(Sheet1!F6:F205,Sheet1!E6:E205,Average!D8) -> 111.18182 | H8: =F8*110/100 -> 1345.3
D9: Business Development | E9: =COUNTIFS(Sheet1!E7:E206,Average!D9) -> 10 | F9: =SUMIFS(Sheet1!F7:F206,Sheet1!E7:E206,Average!D9) -> 1106 | G9: =AVERAGEIFS(Sheet1!F7:F206,Sheet1!E7:E206,Average!D9) -> 110.6 | H9: =F9*110/100 -> 1216.6
D10: Operations | E10: =COUNTIFS(Sheet1!E8:E207,Average!D10) -> 13 | F10: =SUMIFS(Sheet1!F8:F207,Sheet1!E8:E207,Average!D10) -> 1275 | G10: =AVERAGEIFS(Sheet1!F8:F207,Sheet1!E8:E207,Average!D10) -> 98.076923 | H10: =F10*110/100 -> 1402.5
D11: Marketing | E11: =COUNTIFS(Sheet1!E9:E208,Average!D11) -> 14 | F11: =SUMIFS(Sheet1!F9:F208,Sheet1!E9:E208,Average!D11) -> 1386 | G11: =AVERAGEIFS(Sheet1!F9:F208,Sheet1!E9:E208,Average!D11) -> 99 | H11: =F11*110/100 -> 1524.6
D12: Data Analytics | E12: =COUNTIFS(Sheet1!E10:E209,Average!D12) -> 14 | F12: =SUMIFS(Sheet1!F10:F209,Sheet1!E10:E209,Average!D12) -> 1484 | G12: =AVERAGEIFS(Sheet1!F10:F209,Sheet1!E10:E209,Average!D12) -> 106 | H12: =F12*110/100 -> 1632.4
D13: Accounting | E13: =COUNTIFS(Sheet1!E11:E210,Average!D13) -> 19 | F13: =SUMIFS(Sheet1!F11:F210,Sheet1!E11:E210,Average!D13) -> 1684 | G13: =AVERAGEIFS(Sheet1!F11:F210,Sheet1!E11:E210,Average!D13) -> 88.631579 | H13: =F13*110/100 -> 1852.4
D14: Sales | E14: =COUNTIFS(Sheet1!E12:E211,Average!D14) -> 17 | F14: =SUMIFS(Sheet1!F12:F211,Sheet1!E12:E211,Average!D14) -> 1779 | G14: =AVERAGEIFS(Sheet1!F12:F211,Sheet1!E12:E211,Average!D14) -> 104.64706 | H14: =F14*110/100 -> 1956.9
D15: Human Resources | E15: =COUNTIFS(Sheet1!E13:E212,Average!D15) -> 11 | F15: =SUMIFS(Sheet1!F13:F212,Sheet1!E13:E212,Average!D15) -> 1307 | G15: =AVERAGEIFS(Sheet1!F13:F212,Sheet1!E13:E212,Average!D15) -> 118.81818 | H15: =F15*110/100 -> 1437.7
D16: Legal | E16: =COUNTIFS(Sheet1!E14:E213,Average!D16) -> 10 | F16: =SUMIFS(Sheet1!F14:F213,Sheet1!E14:E213,Average!D16) -> 1073 | G16: =AVERAGEIFS(Sheet1!F14:F213,Sheet1!E14:E213,Average!D16) -> 107.3 | H16: =F16*110/100 -> 1180.3
... D18: Research and Development | E18: =COUNTIFS(Sheet1!E16:E215,Average!D18) -> 15 | F18: =SUMIFS(Sheet1!F16:F215,Sheet1!E16:E215,Average!D18) -> 1520 | G18: =AVERAGEIFS(Sheet1!F16:F215,Sheet1!E16:E215,Average!D18) -> 101.33333 | H18: =F18*110/100 -> 1672
K21: Robin

Sheet Filter
D1: Avobe 100 Salary
D3: {=Sheet1!A1:N1} -> Emp_ID | E3: First_Name | F3: Last_Name | G3: Gender | H3: Department | I3: Salary | J3: Salary_Bucket | K3: Start_Date | L3: FTE | M3: Employee type | N3: Work_location | O3: Tenure | P3: Work_Type | Q3: 0
D4: {=_xlfn._xlws.FILTER(Sheet1!A2:O201,Sheet1!F2:F201>100)} -> PR91404 | E4: Michael | F4: Mitchell | G4: Male | H4: Finance | I4: 156 | J4: 732 | K4: Above 100k | L4: 46126 | M4: 0.6 | N4: Permanent | O4: New York | P4: USA | Q4: 8.19 | R4: Freelance
D5: PR26442 | E5: Andreas | F5: Smith | G5: Male | H5: IT | I5: 143 | J5: 894 | K5: Above 100k | L5: 46094 | M5: 0.4 | N5: Permanent | O5: Sydney | P5: Australia | Q5: 1.11 | R5: Contract
D6: PR43906 | E6: Horst | F6: Perez | G6: Female | H6: Marketing | I6: 107 | J6: 996 | K6: Above 100k | L6: 46055 | M6: 0.8 | N6: Contract | O6: Hyderabad | P6: India | Q6: 6.43 | R6: Part time
D7: PR40245 | E7: Ursula | F7: Hill | G7: Male | H7: Data Analytics | I7: 136 | J7: 213 | K7: Above 100k | L7: 46332 | M7: 0.7 | N7: Permanent | O7: London | P7: UK | Q7: 7.74 | R7: Part time
D8: PR47648 | E8: Brigitte | F8: Turner | G8: Female | H8: Data Analytics | I8: 164 | J8: 32 | K8: Above 100k | L8: 46366 | M8: 0.4 | N8: Temporary | O8: Remote | P8: 5.6 | Q8: Part time | R8: 0
D9: PR71131 | E9: Manfred | F9: Phillips | G9: Female | H9: Sales | I9: 128 | J9: 485 | K9: Above 100k | L9: 46030 | M9: 0.9 | N9: Permanent | O9: London | P9: UK | Q9: 0.64 | R9: Freelance
D10: PR55662 | E10: Dieter | F10: Young | G10: Female | H10: Operations | I10: 119 | J10: 389 | K10: Above 100k | L10: 46108 | M10: 0.6 | N10: Permanent | O10: Remote | P10: 1.32 | Q10: Full time | R10: 0
D11: PR25096 | E11: Beryl | F11: Davis | G11: Male | H11: Human Resources | I11: 105 | J11: 544 | K11: Above 100k | L11: 46371 | M11: 0.9 | N11: Permanent | O11: Hyderabad | P11: India | Q11: 7.01 | R11: Full time
D12: PR56147 | E12: Julia | F12: Fellgate | G12: Male | H12: Training | I12: 179 | J12: 673 | K12: Above 100k | L12: 46054 | M12: 0.4 | N12: Temporary | O12: London | P12: UK | Q12: 9.86 | R12: Freelance
D13: PR32576 | E13: Emma | F13: Moore | G13: Female | H13: Product Management | I13: 118 | J13: 728 | K13: Above 100k | L13: 46049 | M13: 0.6 | N13: Contract | O13: Dubai | P13: UAE | Q13: 5.71 | R13: Part time
D14: PR34510 | E14: Sarah | F14: Clark | G14: Male | H14: Product Management | I14: 148 | J14: 806 | K14: Above 100k | L14: 46091 | M14: 0.4 | N14: Contract | O14: Columbus | P14: USA | Q14: 2.05 | R14: Full time
D15: PR23233 | E15: Klaus | F15: Burnsyde | G15: Male | H15: Customer Service | I15: 170 | J15: 775 | K15: Above 100k | L15: 46167 | M15: 0.4 | N15: Permanent | O15: Berlin | P15: Germany | Q15: 2.97 | R15: Part time
D16: PR63739 | E16: Elfriede | F16: Green | G16: Male | H16: Data Analytics | I16: 104 | J16: 718 | K16: Above 100k | L16: 46108 | M16: 0.4 | N16: Temporary | O16: Toronto | P16: Canada | Q16: 8.49 | R16: Part time
D17: PR78417 | E17: Erich | F17: Lewis | G17: Female | H17: Research and Development | I17: 155 | J17: 265 | K17: Above 100k | L17: 46090 | M17: 0.6 | N17: Contract | O17: Toronto | P17: Canada | Q17: 6.13 | R17: Contract
D18: PR42580 | E18: Dieter | F18: Jones | G18: Female | H18: Product Management | I18: 112 | J18: 393 | K18: Above 100k | L18: 46266 | M18: 0.9 | N18: Contract | O18: Chicago | P18: USA | Q18: 2.59 | R18: Full time
D19: PR77997 | E19: Hans | F19: Lewis | G19: Male | H19: Marketing | I19: 146 | J19: 200 | K19: Above 100k | L19: 46234 | M19: 0.4 | N19: Contract | O19: Toronto | P19: Canada | Q19: 3.8 | R19: Part time
D20: PR72197 | E20: Maria | F20: Flores | G20: Male | H20: Human Resources | I20: 130 | J20: 11 | K20: Above 100k | L20: 46355 | M20: 0.4 | N20: Temporary | O20: Remote | P20: 3.8 | Q20: Contract | R20: 0
D21: PR47581 | E21: Brigitte | F21: Hall | G21: Male | H21: Engineering | I21: 135 | J21: 959 | K21: Above 100k | L21: 46172 | M21: 0.9 | N21: Permanent | O21: Remote | P21: 5.46 | Q21: Part time | R21: 0
D22: PR89785 | E22: Maria | F22: Veeravasarapu | G22: Male | H22: Training | I22: 169 | J22: 133 | K22: Above 100k | L22: 46352 | M22: 0.5 | N22: Permanent | O22: Remote | P22: 6.71 | Q22: Contract | R22: 0
D23: PR33378 | E23: Erich | F23: Harris | G23: Female | H23: Legal | I23: 127 | J23: 989 | K23: Above 100k | L23: 46364 | M23: 0.8 | N23: Contract | O23: Toronto | P23: Canada | Q23: 3.6 | R23: Freelance
D24: PR96736 | E24: Hildegard | F24: Campbell | G24: Female | H24: Accounting | I24: 138 | J24: 984 | K24: Above 100k | L24: 46122 | M24: 0.9 | N24: Temporary | O24: Mumbai | P24: India | Q24: 0.97 | R24: Full time
D25: PR70590 | E25: Torrance | F25: Vadali | G25: Male | H25: Customer Service | I25: 147 | J25: 453 | K25: Above 100k | L25: 46093 | M25: 0.5 | N25: Contract | O25: Hyderabad | P25: India | Q25: 4.03 | R25: Contract
D26: PR89803 | E26: Beryl | F26: Perez | G26: Male | H26: Operations | I26: 157 | J26: 10 | K26: Above 100k | L26: 46170 | M26: 1 | N26: Contract | O26: Singapore | P26: 7.28 | Q26: Full time | R26: 0
D27: PR21693 | E27: Jill | F27: Martinez | G27: Male | H27: Marketing | I27: 105 | J27: 181 | K27: Above 100k | L27: 46206 | M27: 0.8 | N27: Permanent | O27: Sydney | P27: Australia | Q27: 5.99 | R27: Contract
D28: PR41569 | E28: Brigitte | F28: White | G28: Male | H28: Engineering | I28: 177 | J28: 653 | K28: Above 100k | L28: 46147 | M28: 0.5 | N28: Contract | O28: Toronto | P28: Canada | Q28: 2.76 | R28: Full time
D29: PR84680 | E29: Robert | F29: Robinson | G29: Male | H29: Human Resources | I29: 125 | J29: 464 | K29: Above 100k | L29: 46374 | M29: 0.9 | N29: Contract | O29: Sydney | P29: Australia | Q29: 4.81 | R29: Freelance
D30: PR45681 | E30: Bernd | F30: Ricardot | G30: Male | H30: Legal | I30: 167 | J30: 702 | K30: Above 100k | L30: 46378 | M30: 0.5 | N30: Permanent | O30: Singapore | P30: 2.64 | Q30: Part time | R30: 0
D31: PR76983 | E31: Inger | F31: Hall | G31: Male | H31: IT | I31: 115 | J31: 18 | K31: Above 100k | L31: 46265 | M31: 0.3 | N31: Contract | O31: Wellington | P31: New Zealand | Q31: 3.65 | R31: Part time
D32: PR11368 | E32: Günter | F32: Campbell | G32: Female | H32: Business Development | I32: 179 | J32: 227 | K32: Above 100k | L32: 46235 | M32: 0.8 | N32: Temporary | O32: London | P32: UK | Q32: 4.55 | R32: Contract
D33: PR14854 | E33: Bernd | F33: Taylor | G33: Male | H33: Marketing | I33: 102 | J33: 435 | K33: Above 100k | L33: 46343 | M33: 0.7 | N33: Contract | O33: Dubai | P33: UAE | Q33: 9.72 | R33: Contract
D34: PR18326 | E34: Hannelore | F34: Garcia | G34: Male | H34: Product Management | I34: 120 | J34: 109 | K34: Above 100k | L34: 46040 | M34: 0.6 | N34: Contract | O34: London | P34: UK | Q34: 1.82 | R34: Full time
D35: PR59070 | E35: Ursula | F35: Taylor | G35: Male | H35: Legal | I35: 127 | J35: 981 | K35: Above 100k | L35: 46307 | M35: 0.6 | N35: Contract | O35: London | P35: UK | Q35: 6.42 | R35: Contract
D36: PR43763 | E36: Bernd | F36: Mitchell | G36: Male | H36: Business Development | I36: 149 | J36: 551 | K36: Above 100k | L36: 46200 | M36: 0.8 | N36: Permanent | O36: Remote | P36: 0.79 | Q36: Full time | R36: 0
D37: PR72967 | E37: Sarah | F37: Nguyen | G37: Male | H37: Data Analytics | I37: 138 | J37: 605 | K37: Above 100k | L37: 46266 | M37: 0.7 | N37: Permanent | O37: Sydney | P37: Australia | Q37: 7.83 | R37: Full time
D38: PR65084 | E38: Gerhard | F38: Augar | G38: Female | H38: Marketing | I38: 172 | J38: 310 | K38: Above 100k | L38: 46314 | M38: 0.4 | N38: Temporary | O38: Dubai | P38: UAE | Q38: 4.58 | R38: Full time
D39: PR52944 | E39: Rainer | F39: Veeravasarapu | G39: Male | H39: Sales | I39: 136 | J39: 433 | K39: Above 100k | L39: 46030 | M39: 0.7 | N39: Permanent | O39: Dubai | P39: UAE | Q39: 7.71 | R39: Freelance
D40: PR78020 | E40: Robert | F40: Brown | G40: Male | H40: Sales | I40: 179 | J40: 240 | K40: Above 100k | L40: 46146 | M40: 0.9 | N40: Permanent | O40: Paris | P40: France | Q40: 8.48 | R40: Freelance
D41: PR40477 | E41: Nicole | F41: Veeravasarapu | G41: Male | H41: Customer Service | I41: 155 | J41: 582 | K41: Above 100k | L41: 46208 | M41: 0.3 | N41: Permanent | O41: Hyderabad | P41: India | Q41: 5.31 | R41: Full time
...

Sheet Max-min
C4: Lowest, Highest and Top 5 Salaries
D7: All EMPS | E7: Male | F7: Female
C8: Lowest Salarry | D8: =MIN(Sheet1!F2:F201) -> 28
C9: Highest Salary | D9: =MAX(Sheet1!F2:F201) -> 179
C10: Top 5 Salary | D10: =LARGE(Sheet1!F2:F201,H11) -> 172
D11: =LARGE(Sheet1!F3:F202,H12) -> 169 | H11: 15
D12: =LARGE(Sheet1!F4:F203,H13) -> 164 | H12: 20
D13: =LARGE(Sheet1!F5:F204,H14) -> 157 | H13: 25
D14: =LARGE(Sheet1!F6:F205,H15) -> 155 | H14: 30
H15: 35
A22: Robin

Sheet Unique-counta
E3: Department | G3: Total Department
E4: {=_xlfn.UNIQUE(Sheet1!E2:E201)} -> Engineering | G4: =COUNTA(_xlfn.ANCHORARRAY(E4)) -> 15
E5: Product Management
E6: Customer Service
E7: Finance
E8: IT
E9: Business Development
E10: Operations
E11: Marketing
E12: Data Analytics
E13: Accounting
E14: Sales
E15: Human Resources
E16: Legal
... E18: Research and Development
L23: Robin

Sheet Vlookup-Index-
A2: , | B2: Employee Lookup
B6: Employee | C6: PR19000
A9: 2 | B9: First name: | C9: =VLOOKUP($C$6,Sheet1!A2:O201,A9,FALSE) -> Ingrid | L9: Robin
A10: 3 | B10: Last name: | C10: =VLOOKUP($C$6,Sheet1!A3:O202,A10,FALSE) -> Davis
A11: 5 | B11: Department: | C11: =VLOOKUP($C$6,Sheet1!A4:O203,A11,FALSE) -> Accounting
A12: 6 | B12: Salary | C12: =VLOOKUP($C$6,Sheet1!A5:O204,A12,FALSE) -> 64
B20: Last name: | C20: Davis
C21: =MATCH('Vlookup-Index-'!C20,Sheet1!C2:C201,0) -> 13
B23: Employee ID | C23: =INDEX(Sheet1!A:A, MATCH(C20, Sheet1!C:C, 0)) -> PR19000 | E23: {=INDEX(Sheet1!A:A, C21)} -> PR47648
B24: Department: | C24: =INDEX(Sheet1!E:E, MATCH(C20, Sheet1!C:C, 0)) -> Accounting
B25: Salary: | C25: =INDEX(Sheet1!F:F, MATCH(C20, Sheet1!C:C, 0)) -> 64

Sheet Xlookup-Inferror
E3: Xlookup + caoonect with Clookup+ sheet1
E5: First Name | F5: =_xlfn.XLOOKUP('Vlookup-Index-'!C6,Sheet1!A:A,Sheet1!B:B) -> Ingrid
E6: Department | F6: =_xlfn.XLOOKUP('Vlookup-Index-'!C6,Sheet1!A:A,Sheet1!E:E) -> Accounting
E7: salary | F7: =_xlfn.XLOOKUP('Vlookup-Index-'!C6,Sheet1!A:A,Sheet1!F:F) -> 64
E8: EMP_ID | F8: =_xlfn.XLOOKUP('Vlookup-Index-'!C6,Sheet1!A:A,Sheet1!A:A) -> PR19000
E11: Entire Data
E13: =_xlfn.XLOOKUP(C9, Sheet1!B:B, Sheet1!E:E) -> 0
B18: Robin

Sheet Xlookup-Max
D3: salary max | E3: =MAX(Sheet1!F2:F201) -> 179
D4: One Person | E4: =_xlfn.XLOOKUP(MAX(Sheet1!F:F), Sheet1!F:F, Sheet1!B:B) & " " & _xlfn.XLOOKUP(MAX(Sheet1!F:F), Sheet1!F:F, Sheet1!C:C) -> Julia Fellgate
D9: All person | E9: {=_xlfn._xlws.FILTER(Sheet1!B:B &" "& Sheet1!C:C,Sheet1!F:F=MAX(Sheet1!F:F))} -> Julia Fellgate | F9: {=_xlfn.TEXTJOIN(",",,_xlfn._xlws.FILTER(Sheet1!B:B &" "& Sheet1!C:C,Sheet1!F:F=MAX(Sheet1!F:F)))} -> Julia Fellgate,Günter Campbell,Robert Brown
E10: Günter Campbell
E11: Robert Brown
B19: Robin

Sheet Filter+N
C3: Emp_ID | D3: First_Name | E3: Last_Name
C4: {=_xlfn._xlws.FILTER(Sheet1!A2:O201,Sheet1!B2:B201="Anna")} -> PR96753 | D4: Anna | E4: Scott | F4: Male | G4: Product Management | H4: 34 | I4: 792 | J4: Under 50k | K4: 46250 | L4: 0.7 | M4: Contract | N4: Chicago | O4: USA | P4: 2.15 | Q4: Full time
C5: PR55285 | D5: Anna | E5: Perez | F5: Female | G5: Training | H5: 108 | I5: 512 | J5: Above 100k | K5: 46176 | L5: 0.6 | M5: Temporary | N5: London | O5: UK | P5: 9.43 | Q5: Freelance
C6: PR30716 | D6: Anna | E6: Garcia | F6: Female | G6: Sales | H6: 115 | I6: 877 | J6: Above 100k | K6: 46053 | L6: 0.5 | M6: Permanent | N6: Berlin | O6: Germany | P6: 2.34 | Q6: Freelance
C7: PR71574 | D7: Anna | E7: Perez | F7: Male | G7: Accounting | H7: 98 | I7: 995 | J7: 50k to 100k | K7: 46146 | L7: 0.4 | M7: Temporary | N7: Tokyo | O7: Japan | P7: 7.33 | Q7: Contract
A15: Robin

Sheet Headcount+Salary+All Average
A2: Robin
E5: Total EMP | F5: Salary Avg. | G5: Salary Bucket
D6: ALL Department | E6: =COUNTA(Sheet1!A2:A201) -> 200 | F6: =AVERAGE(Sheet1!F2:F201) -> 103.835 | G6: =MAX(Sheet1!G2:G201) -> 996
D8: Department | E8: Headcount | F8: Avg. salary | G8: %diff form over all Average | H8: Highest-salary | I8: Median Salary
D9: {=_xlfn.UNIQUE(Sheet1!E2:E201)} -> Engineering | E9: {=COUNTIFS(Sheet1!E2:E201,_xlfn.ANCHORARRAY('Headcount+Salary+All Average'!D9))} -> 15 | F9: {=AVERAGEIFS(Sheet1!F2:F201,Sheet1!E2:E201,_xlfn.ANCHORARRAY('Headcount+Salary+All Average'!D9))} -> 99.333333 | G9: =F9-F6 -> -4.5016667 | H9: {=_xlfn.MAXIFS(Sheet1!F2:F201,Sheet1!E2:E201,_xlfn.ANCHORARRAY('Headcount+Salary+All Average'!D9))} -> 177 | I9: =MEDIAN(Sheet1!F2:F201) -> 106
D10: Product Management | E10: 11 | F10: 109.63636 | G10: =F10-F7 -> 109.63636 | H10: 154 | I10: =MEDIAN(Sheet1!F3:F202) -> 107
D11: Customer Service | E11: 15 | F11: 107.26667 | G11: =F11-F8 -> #VALUE! | H11: 177 | I11: =MEDIAN(Sheet1!F4:F203) -> 107
D12: Finance | E12: 13 | F12: 89.692308 | G12: =F12-F9 -> -9.6410256 | H12: 170 | I12: =MEDIAN(Sheet1!F5:F204) -> 107
D13: IT | E13: 11 | F13: 111.18182 | G13: =F13-F10 -> 1.5454545 | H13: 159 | I13: =MEDIAN(Sheet1!F6:F205) -> 107.5
D14: Business Development | E14: 10 | F14: 110.6 | G14: =F14-F11 -> 3.3333333 | H14: 179 | I14: =MEDIAN(Sheet1!F7:F206) -> 107
D15: Operations | E15: 13 | F15: 98.076923 | G15: =F15-F12 -> 8.3846154 | H15: 171 | I15: =MEDIAN(Sheet1!F8:F207) -> 107
D16: Marketing | E16: 14 | F16: 99 | G16: =F16-F13 -> -12.181818 | H16: 172 | I16: =MEDIAN(Sheet1!F9:F208) -> 107
D17: Data Analytics | E17: 14 | F17: 106 | G17: =F17-F14 -> -4.6 | H17: 165 | I17: =MEDIAN(Sheet1!F10:F209) -> 107.5
D18: Accounting | E18: 19 | F18: 88.631579 | G18: =F18-F15 -> -9.4453441 | H18: 175 | I18: =MEDIAN(Sheet1!F11:F210) -> 108
D19: Sales | E19: 17 | F19: 104.64706 | G19: =F19-F16 -> 5.6470588 | H19: 179 | I19: =MEDIAN(Sheet1!F12:F211) -> 109.5
D20: Human Resources | E20: 11 | F20: 118.81818 | G20: =F20-F17 -> 12.818182 | H20: 168 | I20: =MEDIAN(Sheet1!F13:F212) -> 108
D21: Legal | E21: 10 | F21: 107.3 | G21: =F21-F18 -> 18.668421 | H21: 176 | I21: =MEDIAN(Sheet1!F14:F213) -> 107.5
... D23: Research and Development | E23: 15 | F23: 101.33333 | G23: =F23-F20 -> -17.484848 | H23: 176 | I23: =MEDIAN(Sheet1!F16:F215) -> 109.5
